Workbook

Sheet 填写说明
A1: uipsd 图片文字汉化工作表
A2: 已扫描 52 张 PNG；翻译由你填写，坐标、候选色值和字体风格用于后续图片回填。
A4: 图片总数 | B4: 含文字图片 | D4: 填写顺序
A5: =COUNTA(图片清单!$A$6:$A$57) -> 52 | B5: =COUNTIF(图片清单!$E$6:$E$57,"含文字／已整理") -> 19 | D5: 1. 打开“翻译清单”，只填写黄色的“中文译文”列。 2. 相同 ID 会在“位置明细”中自动引用同一译文。 3. 优先处理“处理建议=待翻译”的日文；英文、品牌字和版权可按需保留。 4. 字色说明为人工视觉分类；候选十六进制色来自识别框像素，最终重绘前请对照原 PNG。 5. “OCR原始明细”保留全部机器识别框，只用于查漏，不建议直接翻译。
A6: 唯一原文条目 | B6: 待翻译未填写
A7: =COUNTA(翻译清单!$A$6:$A$155) -> 149 | B7: =COUNTIFS(翻译清单!$E$6:$E$155,"待翻译",翻译清单!$C$6:$C$155,"") -> 0
A8: OCR 原始框 | B8: 已修改中文图集
A9: =COUNTA(OCR原始明细!$A$6:$A$448) -> 443 | B9: =COUNTIF(图片清单!$E$6:$E$57,"已有中文") -> 3
A12: 状态说明
A13: 待翻译 | B13: 日文 UI 文案，建议优先填写 | C13: 按需翻译 | D13: 英语、数字或品牌内容，由你决定 | E13: 建议保留 | F13: 版权等固定文本 | G13: 人工补录 | H13: OCR 未能可靠定位，原文已人工整理
A14: 黄色列 | B14: 唯一需要手工填写的译文列 | C14: 黑／蓝 | D14: 常见普通与悬停状态 | E14: 白字描边 | F14: 常见按钮和标题状态 | G14: 候选色值 | H14: 识别框内的高频色，不等于最终精确色
A15: 位置明细 | B15: 按图片列出原文、坐标和样式 | C15: OCR原始明细 | D15: 443 个机器识别框，用于查漏 | E15: 图片清单 | F15: 52 张 PNG 的扫描状态 | G15: 状态变体数 | H15: 同一文本在图集中出现的状态/图块估计数
A16: 已有中文 | B16: backlog__pack、system0__pack、title__pack | C16: 未见需翻译文字 | D16: 背景、图标或纯装饰图 | E16: 含文字／已整理 | F16: 已进入翻译清单 | G16: 坐标需复核 | H16: 相邻图块曾被 OCR 合并
A17: 重要 | B17: 翻译后不要改 ID 或文件名 | C17: 建议 | D17: 中文长度尽量接近日文宽度 | E17: 美术 | F17: 标题字和粗描边需单独重绘 | G17: 透明图集 | H17: 导出时保持原尺寸和透明通道

Sheet 翻译清单
A1: 翻译清单（只填写黄色列）
A2: 每个 ID 只翻译一次；跨图片重复文本共用同一条中文译文。
A5: ID | B5: 原文 | C5: 中文译文 | D5: 语言 | E5: 处理建议 | F5: 来源图片数 | G5: 状态/图块数 | H5: 来源文件 | I5: 字体颜色 | J5: 字体/描边 | K5: 复核状态 | L5: 备注
A6: UI-0001 | B6: この機能が不要な場合は「OFF」を選択してください。 | C6: 如果不需要此功能，请选择“OFF。 | D6: 日语 | E6: 待翻译 | F6: 1 | G6: =SUMIF(位置明细!$A$6:$A$207,A6,位置明细!$E$6:$E$207) -> 1 | H6: dialog__pack.png | I6: 白字／黑字，蓝色强调 | J6: 粗黑体；主提示带黑色粗描边 | K6: 已人工校正
A7: UI-0002 | B7: システム設定画面でいつでも再設定が可能です。 | C7: 可随时在系统设置界面重新设置。 | D7: 日语 | E7: 待翻译 | F7: 1 | G7: =SUMIF(位置明细!$A$6:$A$207,A7,位置明细!$E$6:$E$207) -> 1 | H7: dialog__pack.png | I7: 白字／黑字，蓝色强调 | J7: 粗黑体；主提示带黑色粗描边 | K7: 已人工校正
A8: UI-0003 | B8: データを入れ替えますか？ | C8: 要交换数据吗？ | D8: 日语 | E8: 待翻译 | F8: 1 | G8: =SUMIF(位置明细!$A$6:$A$207,A8,位置明细!$E$6:$E$207) -> 1 | H8: dialog__pack.png | I8: 白字／黑字，蓝色强调 | J8: 粗黑体；主提示带黑色粗描边 | K8: 已人工校正／坐标需复核
A9: UI-0004 | B9: 前回の続きから始めますか？ | C9: 要从上次中断处继续吗？ | D9: 日语 | E9: 待翻译 | F9: 1 | G9: =SUMIF(位置明细!$A$6:$A$207,A9,位置明细!$E$6:$E$207) -> 1 | H9: dialog__pack.png | I9: 白字／黑字，蓝色强调 | J9: 粗黑体；主提示带黑色粗描边 | K9: 已人工校正
A10: UI-0005 | B10: タイトル画面に戻りますか？ | C10: 要返回标题界面吗？ | D10: 日语 | E10: 待翻译 | F10: 1 | G10: =SUMIF(位置明细!$A$6:$A$207,A10,位置明细!$E$6:$E$207) -> 1 | H10: dialog__pack.png | I10: 白字／黑字，蓝色强调 | J10: 粗黑体；主提示带黑色粗描边 | K10: 已人工校正
A11: UI-0006 | B11: データをコピーしますか？ | C11: 要复制数据吗？ | D11: 日语 | E11: 待翻译 | F11: 1 | G11: =SUMIF(位置明细!$A$6:$A$207,A11,位置明细!$E$6:$E$207) -> 1 | H11: dialog__pack.png | I11: 白字／黑字，蓝色强调 | J11: 粗黑体；主提示带黑色粗描边 | K11: 已人工校正
A12: UI-0007 | B12: クイックセーブしますか？ | C12: 要快速保存吗？ | D12: 日语 | E12: 待翻译 | F12: 1 | G12: =SUMIF(位置明细!$A$6:$A$207,A12,位置明细!$E$6:$E$207) -> 2 | H12: dialog__pack.png | I12: 白字／黑字，蓝色强调 | J12: 粗黑体；主提示带黑色粗描边 | K12: 已人工校正
A13: UI-0008 | B13: クイックロードしますか？ | C13: 要快速读取吗？ | D13: 日语 | E13: 待翻译 | F13: 1 | G13: =SUMIF(位置明细!$A$6:$A$207,A13,位置明细!$E$6:$E$207) -> 2 | H13: dialog__pack.png | I13: 白字／黑字，蓝色强调 | J13: 粗黑体；主提示带黑色粗描边 | K13: 已人工校正
A14: UI-0009 | B14: 初期設定に戻しますか？ | C14: 要恢复为初始设置吗？ | D14: 日语 | E14: 待翻译 | F14: 1 | G14: =SUMIF(位置明细!$A$6:$A$207,A14,位置明细!$E$6:$E$207) -> 1 | H14: dialog__pack.png | I14: 白字／黑字，蓝色强调 | J14: 粗黑体；主提示带黑色粗描边 | K14: 已人工校正
A15: UI-0010 | B15: データを削除しますか？ | C15: 要删除数据吗？ | D15: 日语 | E15: 待翻译 | F15: 1 | G15: =SUMIF(位置明细!$A$6:$A$207,A15,位置明细!$E$6:$E$207) -> 1 | H15: dialog__pack.png | I15: 白字／黑字，蓝色强调 | J15: 粗黑体；主提示带黑色粗描边 | K15: 已人工校正
A16: UI-0011 | B16: ゲームを終了しますか？ | C16: 要退出游戏吗？ | D16: 日语 | E16: 待翻译 | F16: 1 | G16: =SUMIF(位置明细!$A$6:$A$207,A16,位置明细!$E$6:$E$207) -> 1 | H16: dialog__pack.png | I16: 白字／黑字，蓝色强调 | J16: 粗黑体；主提示带黑色粗描边 | K16: 已人工校正
A17: UI-0012 | B17: ジャンプしますか？ | C17: 要跳转吗？ | D17: 日语 | E17: 待翻译 | F17: 1 | G17: =SUMIF(位置明细!$A$6:$A$207,A17,位置明细!$E$6:$E$207) -> 1 | H17: dialog__pack.png | I17: 白字／黑字，蓝色强调 | J17: 粗黑体；主提示带黑色粗描边 | K17: 已人工校正
... A21: UI-0016 | B21: 次回から表示しない | C21: 下次不再显示 | D21: 日语 | E21: 待翻译 | F21: 1 | G21: =SUMIF(位置明细!$A$6:$A$207,A21,位置明细!$E$6:$E$207) -> 3 | H21: dialog__pack.png | I21: 白字／黑字，蓝色强调 | J21: 粗黑体；主提示带黑色粗描边 | K21: 已人工校正
A22: UI-0017 | B22: サスペンド機能 | C22: 暂停功能 | D22: 日语 | E22: 待翻译 | F22: 2 | G22: =SUMIF(位置明细!$A$6:$A$207,A22,位置明细!$E$6:$E$207) -> 2 | H22: dialog__pack.png system1__pack.png | I22: 白字／黑字，蓝色强调；黑字／蓝字／白字 | J22: 粗黑体；主提示带黑色粗描边；粗黑体；普通、悬停、启用、禁用状态 | K22: 已人工校正；已人工校正／坐标需复核 | L22: 同 ID 表示跨图片重复文本，可共用译文。
A23: UI-0018 | B23: YES | C23: 是 | D23: 英语／符号 | E23: 按需翻译 | F23: 1 | G23: =SUMIF(位置明细!$A$6:$A$207,A23,位置明细!$E$6:$E$207) -> 1 | H23: dialog__pack.png | I23: 白字／黑字，蓝色强调 | J23: 粗黑体；主提示带黑色粗描边 | K23: 已人工校正／坐标需复核
A24: UI-0019 | B24: NO | C24: 否 | D24: 英语／符号 | E24: 按需翻译 | F24: 1 | G24: =SUMIF(位置明细!$A$6:$A$207,A24,位置明细!$E$6:$E$207) -> 1 | H24: dialog__pack.png | I24: 白字／黑字，蓝色强调 | J24: 粗黑体；主提示带黑色粗描边 | K24: 已人工校正／坐标需复核
A25: UI-0020 | B25: ON | C25: 开 | D25: 英语／符号 | E25: 按需翻译 | F25: 6 | G25: =SUMIF(位置明细!$A$6:$A$207,A25,位置明细!$E$6:$E$207) -> 20 | H25: dialog__pack.png system1__pack.png system2__pack.png system3__pack.png system4__pack.png system5__pack.png | I25: 白字／黑字，蓝色强调；黑字／蓝字／白字；深蓝字／黑字／白字 | J25: 粗黑体；主提示带黑色粗描边；粗黑体；普通、悬停、启用、禁用状态；粗黑体；人物名与开关状态混排；粗黑体；确认弹窗开关状态；粗黑体；说明文字较小 | K25: 已人工校正／坐标需复核；已人工校正 | L25: 同 ID 表示跨图片重复文本，可共用译文。
A26: UI-0021 | B26: OFF | C26: 关闭 | D26: 英语／符号 | E26: 按需翻译 | F26: 6 | G26: =SUMIF(位置明细!$A$6:$A$207,A26,位置明细!$E$6:$E$207) -> 14 | H26: dialog__pack.png system1__pack.png system2__pack.png system3__pack.png system4__pack.png system5__pack.png | I26: 白字／黑字，蓝色强调；黑字／蓝字／白字；深蓝字／黑字／白字 | J26: 粗黑体；主提示带黑色粗描边；粗黑体；普通、悬停、启用、禁用状态；粗黑体；人物名与开关状态混排；粗黑体；确认弹窗开关状态；粗黑体；说明文字较小 | K26: 已人工校正；已人工校正／坐标需复核 | L26: 同 ID 表示跨图片重复文本，可共用译文。
A27: UI-0022 | B27: *DATE | C27: *日期 | D27: 英语／符号 | E27: 按需翻译 | F27: 1 | G27: =SUMIF(位置明细!$A$6:$A$207,A27,位置明细!$E$6:$E$207) -> 1 | H27: file__pack.png | I27: 黑字／白字，蓝色状态字 | J27: 粗黑体与窄体混排；部分带黑色描边 | K27: 已人工校正
A28: UI-0023 | B28: *CHAPTER | C28: *章节 | D28: 英语／符号 | E28: 按需翻译 | F28: 1 | G28: =SUMIF(位置明细!$A$6:$A$207,A28,位置明细!$E$6:$E$207) -> 1 | H28: file__pack.png | I28: 黑字／白字，蓝色状态字 | J28: 粗黑体与窄体混排；部分带黑色描边 | K28: 已人工校正
A29: UI-0024 | B29: *COMMENT | C29: *备注 | D29: 英语／符号 | E29: 按需翻译 | F29: 1 | G29: =SUMIF(位置明细!$A$6:$A$207,A29,位置明细!$E$6:$E$207) -> 1 | H29: file__pack.png | I29: 黑字／白字，蓝色状态字 | J29: 粗黑体与窄体混排；部分带黑色描边 | K29: 已人工校正
A30: UI-0025 | B30: とける風花とシロうさぎ | C30: 融化的风花与白兔 | D30: 日语 | E30: 待翻译 | F30: 3 | G30: =SUMIF(位置明细!$A$6:$A$207,A30,位置明细!$E$6:$E$207) -> 3 | H30: file__pack.png popup_quick__bg0.png title_bg_5.png | I30: 黑字／白字，蓝色状态字；多色标题、浅灰副标题；粉、蓝、灰多色 | J30: 粗黑体与窄体混排；部分带黑色描边；装饰性标题字；品牌图形；手写／装饰标题字；需单独美术重制 | K30: 已人工校正／坐标需复核 | L30: 同 ID 表示跨图片重复文本，可共用译文。
A31: UI-0026 | B31: TOKERU FUUKA TO SHIROUSAGI | C31: TOKERU FUUKA TO SHIROUSAGI | D31: 英语／符号 | E31: 按需翻译 | F31: 3 | G31: =SUMIF(位置明细!$A$6:$A$207,A31,位置明细!$E$6:$E$207) -> 3 | H31: file__pack.png popup_quick__bg0.png title_bg_5.png | I31: 黑字／白字，蓝色状态字；多色标题、浅灰副标题；粉、蓝、灰多色 | J31: 粗黑体与窄体混排；部分带黑色描边；装饰性标题字；品牌图形；手写／装饰标题字；需单独美术重制 | K31: 已人工校正；人工补录／坐标需复核 | L31: 同 ID 表示跨图片重复文本，可共用译文。
A32: UI-0027 | B32: No Data | C32: 无数据 | D32: 英语／符号 | E32: 按需翻译 | F32: 2 | G32: =SUMIF(位置明细!$A$6:$A$207,A32,位置明细!$E$6:$E$207) -> 2 | H32: file__pack.png popup_quick__bg0.png | I32: 黑字／白字，蓝色状态字；多色标题、浅灰副标题 | J32: 粗黑体与窄体混排；部分带黑色描边；装饰性标题字；品牌图形 | K32: 已人工校正 | L32: 同 ID 表示跨图片重复文本，可共用译文。
A33: UI-0028 | B33: クイックロード | C33: 快速读取 | D33: 日语 | E33: 待翻译 | F33: 3 | G33: =SUMIF(位置明细!$A$6:$A$207,A33,位置明细!$E$6:$E$207) -> 5 | H33: file__pack.png system4__pack.png system5_pulldown__pack.png | I33: 黑字／白字，蓝色状态字；黑字／蓝字／白字；白字／浅蓝字 | J33: 粗黑体与窄体混排；部分带黑色描边；粗黑体；确认弹窗开关状态；粗黑体；蓝色菜单普通与悬停状态 | K33: 已人工校正 | L33: 同 ID 表示跨图片重复文本，可共用译文。
A34: UI-0029 | B34: チャプターとコメントを表示 | C34: 显示章节和备注 | D34: 日语 | E34: 待翻译 | F34: 1 | G34: =SUMIF(位置明细!$A$6:$A$207,A34,位置明细!$E$6:$E$207) -> 5 | H34: file__pack.png | I34: 黑字／白字，蓝色状态字 | J34: 粗黑体与窄体混排；部分带黑色描边 | K34: 已人工校正
A35: UI-0030 | B35: セーブ | C35: 保存 | D35: 日语 | E35: 待翻译 | F35: 2 | G35: =SUMIF(位置明细!$A$6:$A$207,A35,位置明细!$E$6:$E$207) -> 7 | H35: file__pack.png system5_pulldown__pack.png | I35: 黑字／白字，蓝色状态字；白字／浅蓝字 | J35: 粗黑体与窄体混排；部分带黑色描边；粗黑体；蓝色菜单普通与悬停状态 | K35: 已人工校正 | L35: 同 ID 表示跨图片重复文本，可共用译文。
A36: UI-0031 | B36: ロード | C36: 读取 | D36: 日语 | E36: 待翻译 | F36: 2 | G36: =SUMIF(位置明细!$A$6:$A$207,A36,位置明细!$E$6:$E$207) -> 8 | H36: file__pack.png system5_pulldown__pack.png | I36: 黑字／白字，蓝色状态字；白字／浅蓝字 | J36: 粗黑体与窄体混排；部分带黑色描边；粗黑体；蓝色菜单普通与悬停状态 | K36: 已人工校正／坐标需复核；已人工校正 | L36: 同 ID 表示跨图片重复文本，可共用译文。
A37: UI-0032 | B37: EDITボタンのホールド | C37: 长按EDIT按钮 | D37: 日语 | E37: 待翻译 | F37: 1 | G37: =SUMIF(位置明细!$A$6:$A$207,A37,位置明细!$E$6:$E$207) -> 6 | H37: file__pack.png | I37: 黑字／白字，蓝色状态字 | J37: 粗黑体与窄体混排；部分带黑色描边 | K37: 已人工校正
A38: UI-0033 | B38: データ入れ替え | C38: 数据替换 | D38: 日语 | E38: 待翻译 | F38: 2 | G38: =SUMIF(位置明细!$A$6:$A$207,A38,位置明细!$E$6:$E$207) -> 2 | H38: file__pack.png system4__pack.png | I38: 黑字／白字，蓝色状态字；黑字／蓝字／白字 | J38: 粗黑体与窄体混排；部分带黑色描边；粗黑体；确认弹窗开关状态 | K38: 已人工校正 | L38: 同 ID 表示跨图片重复文本，可共用译文。
A39: UI-0034 | B39: データコピー | C39: 数据复制 | D39: 日语 | E39: 待翻译 | F39: 1 | G39: =SUMIF(位置明细!$A$6:$A$207,A39,位置明细!$E$6:$E$207) -> 1 | H39: file__pack.png | I39: 黑字／白字，蓝色状态字 | J39: 粗黑体与窄体混排；部分带黑色描边 | K39: 已人工校正
A40: UI-0035 | B40: EXTRA BACK | C40: 额外返回 | D40: 英语／符号 | E40: 按需翻译 | F40: 1 | G40: =SUMIF(位置明细!$A$6:$A$207,A40,位置明细!$E$6:$E$207) -> 2 | H40: file__pack.png | I40: 黑字／白字，蓝色状态字 | J40: 粗黑体与窄体混排；部分带黑色描边 | K40: 已人工校正
A41: UI-0036 | B41: EXTRA LOAD | C41: 额外读取 | D41: 英语／符号 | E41: 按需翻译 | F41: 1 | G41: =SUMIF(位置明细!$A$6:$A$207,A41,位置明细!$E$6:$E$207) -> 1 | H41: file__pack.png | I41: 黑字／白字，蓝色状态字 | J41: 粗黑体与窄体混排；部分带黑色描边 | K41: 已人工校正／坐标需复核
A42: UI-0037 | B42: SAVE | C42: 保存 | D42: 英语／符号 | E42: 按需翻译 | F42: 1 | G42: =SUMIF(位置明细!$A$6:$A$207,A42,位置明细!$E$6:$E$207) -> 2 | H42: file__pack.png | I42: 黑字／白字，蓝色状态字 | J42: 粗黑体与窄体混排；部分带黑色描边 | K42: 已人工校正
A43: UI-0038 | B43: LOAD | C43: 读取 | D43: 英语／符号 | E43: 按需翻译 | F43: 1 | G43: =SUMIF(位置明细!$A$6:$A$207,A43,位置明细!$E$6:$E$207) -> 3 | H43: file__pack.png | I43: 黑字／白字，蓝色状态字 | J43: 粗黑体与窄体混排；部分带黑色描边 | K43: 已人工校正
A44: UI-0039 | B44: NEW! | C44: 新! | D44: 英语／符号 | E44: 按需翻译 | F44: 1 | G44: =SUMIF(位置明细!$A$6:$A$207,A44,位置明细!$E$6:$E$207) -> 2 | H44: file__pack.png | I44: 黑字／白字，蓝色状态字 | J44: 粗黑体与窄体混排；部分带黑色描边 | K44: 已人工校正
A45: UI-0040 | B45: Q.LOAD | C45: 快速读取 | D45: 英语／符号 | E45: 按需翻译 | F45: 1 | G45: =SUMIF(位置明细!$A$6:$A$207,A45,位置明细!$E$6:$E$207) -> 1 | H45: file__pack.png | I45: 黑字／白字，蓝色状态字 | J45: 粗黑体与窄体混排；部分带黑色描边 | K45: 已人工校正
...

Sheet 位置明细
A1: 位置明细
A2: 按来源图片保留坐标、候选色值和状态数量；中文译文自动引用“翻译清单”。
A5: ID | B5: 文件名 | C5: 原文 | D5: 中文译文（自动） | E5: 变体数 | F5: X | G5: Y | H5: 宽 | I5: 高 | J5: 估计字号(px) | K5: 文字色说明 | L5: 候选色值 | M5: 字体/描边 | N5: OCR置信度 | O5: 匹配分数 | P5: 复核状态 | Q5: 备注
A6: UI-0001 | B6: dialog__pack.png | C6: この機能が不要な場合は「OFF」を選択してください。 | D6: =IFERROR(VLOOKUP(A6,翻译清单!$A$6:$L$155,3,FALSE),"") -> 如果不需要此功能，请选择“OFF。 | E6: 1 | F6: 0 | G6: 297 | H6: 541 | I6: 23 | J6: 19 | K6: 白字／黑字，蓝色强调 | L6: #304070 / #F0F0F0 | M6: 粗黑体；主提示带黑色粗描边 | N6: 0.9969 | O6: 1 | P6: 已人工校正
A7: UI-0002 | B7: dialog__pack.png | C7: システム設定画面でいつでも再設定が可能です。 | D7: =IFERROR(VLOOKUP(A7,翻译清单!$A$6:$L$155,3,FALSE),"") -> 可随时在系统设置界面重新设置。 | E7: 1 | F7: 24 | G7: 316 | H7: 690 | I7: 41 | J7: 34 | K7: 白字／黑字，蓝色强调 | L7: #304070 / #4080D0 / #F0F0F0 / #000000 | M7: 粗黑体；主提示带黑色粗描边 | N7: 0.9925 | O7: 0.903 | P7: 已人工校正
A8: UI-0003 | B8: dialog__pack.png | C8: データを入れ替えますか？ | D8: =IFERROR(VLOOKUP(A8,翻译清单!$A$6:$L$155,3,FALSE),"") -> 要交换数据吗？ | E8: 1 | F8: 1 | G8: 581 | H8: 399 | I8: 37 | J8: 30 | K8: 白字／黑字，蓝色强调 | L8: #F0F0F0 | M8: 粗黑体；主提示带黑色粗描边 | N8: 0.9599 | O8: 0.667 | P8: 已人工校正／坐标需复核
A9: UI-0004 | B9: dialog__pack.png | C9: 前回の続きから始めますか？ | D9: =IFERROR(VLOOKUP(A9,翻译清单!$A$6:$L$155,3,FALSE),"") -> 要从上次中断处继续吗？ | E9: 1 | F9: 1 | G9: 382 | H9: 515 | I9: 36 | J9: 30 | K9: 白字／黑字，蓝色强调 | L9: #F0F0F0 / #5070B0 / #5060A0 / #E0E0E0 | M9: 粗黑体；主提示带黑色粗描边 | N9: 0.9628 | O9: 1 | P9: 已人工校正
A10: UI-0005 | B10: dialog__pack.png | C10: タイトル画面に戻りますか？ | D10: =IFERROR(VLOOKUP(A10,翻译清单!$A$6:$L$155,3,FALSE),"") -> 要返回标题界面吗？ | E10: 1 | F10: 1 | G10: 415 | H10: 507 | I10: 36 | J10: 30 | K10: 白字／黑字，蓝色强调 | L10: #F0F0F0 / #4080D0 / #E0E0E0 / #D0D0D0 | M10: 粗黑体；主提示带黑色粗描边 | N10: 0.9744 | O10: 1 | P10: 已人工校正
A11: UI-0006 | B11: dialog__pack.png | C11: データをコピーしますか？ | D11: =IFERROR(VLOOKUP(A11,翻译清单!$A$6:$L$155,3,FALSE),"") -> 要复制数据吗？ | E11: 1 | F11: 0 | G11: 445 | H11: 444 | I11: 41 | J11: 34 | K11: 白字／黑字，蓝色强调 | L11: #F0F0F0 / #4080D0 / #000000 / #4070C0 | M11: 粗黑体；主提示带黑色粗描边 | N11: 0.9631 | O11: 1 | P11: 已人工校正
A12: UI-0007 | B12: dialog__pack.png | C12: クイックセーブしますか？ | D12: =IFERROR(VLOOKUP(A12,翻译清单!$A$6:$L$155,3,FALSE),"") -> 要快速保存吗？ | E12: 2 | F12: 0 | G12: 479 | H12: 441 | I12: 45 | J12: 37 | K12: 白字／黑字，蓝色强调 | L12: #F0F0F0 / #000000 | M12: 粗黑体；主提示带黑色粗描边 | N12: 0.9893 | O12: 1 | P12: 已人工校正
A13: UI-0008 | B13: dialog__pack.png | C13: クイックロードしますか？ | D13: =IFERROR(VLOOKUP(A13,翻译清单!$A$6:$L$155,3,FALSE),"") -> 要快速读取吗？ | E13: 2 | F13: 1 | G13: 513 | H13: 437 | I13: 38 | J13: 31 | K13: 白字／黑字，蓝色强调 | L13: #F0F0F0 | M13: 粗黑体；主提示带黑色粗描边 | N13: 0.9982 | O13: 1 | P13: 已人工校正
A14: UI-0009 | B14: dialog__pack.png | C14: 初期設定に戻しますか？ | D14: =IFERROR(VLOOKUP(A14,翻译清单!$A$6:$L$155,3,FALSE),"") -> 要恢复为初始设置吗？ | E14: 1 | F14: 1 | G14: 548 | H14: 404 | I14: 36 | J14: 30 | K14: 白字／黑字，蓝色强调 | L14: #F0F0F0 | M14: 粗黑体；主提示带黑色粗描边 | N14: 0.9991 | O14: 1 | P14: 已人工校正
A15: UI-0010 | B15: dialog__pack.png | C15: データを削除しますか？ | D15: =IFERROR(VLOOKUP(A15,翻译清单!$A$6:$L$155,3,FALSE),"") -> 要删除数据吗？ | E15: 1 | F15: 1 | G15: 581 | H15: 399 | I15: 37 | J15: 30 | K15: 白字／黑字，蓝色强调 | L15: #F0F0F0 | M15: 粗黑体；主提示带黑色粗描边 | N15: 0.9599 | O15: 1 | P15: 已人工校正
A16: UI-0011 | B16: dialog__pack.png | C16: ゲームを終了しますか？ | D16: =IFERROR(VLOOKUP(A16,翻译清单!$A$6:$L$155,3,FALSE),"") -> 要退出游戏吗？ | E16: 1 | F16: 0 | G16: 609 | H16: 402 | I16: 44 | J16: 36 | K16: 白字／黑字，蓝色强调 | L16: #F0F0F0 | M16: 粗黑体；主提示带黑色粗描边 | N16: 0.9976 | O16: 1 | P16: 已人工校正
A17: UI-0012 | B17: dialog__pack.png | C17: ジャンプしますか？ | D17: =IFERROR(VLOOKUP(A17,翻译清单!$A$6:$L$155,3,FALSE),"") -> 要跳转吗？ | E17: 1 | F17: 438 | G17: 538 | H17: 326 | I17: 39 | J17: 32 | K17: 白字／黑字，蓝色强调 | L17: #F0F0F0 | M17: 粗黑体；主提示带黑色粗描边 | N17: 0.999 | O17: 1 | P17: 已人工校正
... A64: UI-0059 | B64: gesture_tips__pack.png | C64: クイックセーブ | D64: =IFERROR(VLOOKUP(A64,翻译清单!$A$6:$L$155,3,FALSE),"") -> 快速保存 | E64: 1 | F64: 0 | G64: 221 | H64: 134 | I64: 21 | J64: 17 | K64: 黑字／蓝字／白字 | L64: #000000 | M64: 粗黑体；按钮状态有描边 | N64: 0.9952 | O64: 1 | P64: 已人工校正
A65: UI-0025 | B65: popup_quick__bg0.png | C65: とける風花とシロうさぎ | D65: =IFERROR(VLOOKUP(A65,翻译清单!$A$6:$L$155,3,FALSE),"") -> 融化的风花与白兔 | E65: 1 | F65: 51 | G65: 62 | H65: 142 | I65: 23 | J65: 19 | K65: 多色标题、浅灰副标题 | L65: #D0E0F0 / #E0F0F0 / #E0E0F0 / #C0D0E0 | M65: 装饰性标题字；品牌图形 | N65: 0.908 | O65: 0.857 | P65: 已人工校正／坐标需复核 | Q65: 同 ID 表示跨图片重复文本，可共用译文。
A66: UI-0026 | B66: popup_quick__bg0.png | C66: TOKERU FUUKA TO SHIROUSAGI | D66: =IFERROR(VLOOKUP(A66,翻译清单!$A$6:$L$155,3,FALSE),"") -> TOKERU FUUKA TO SHIROUSAGI | E66: 1 | F66: 80 | G66: 96 | H66: 82 | I66: 14 | J66: 11 | K66: 多色标题、浅灰副标题 | L66: #D0E0F0 / #A0B0C0 / #B0C0D0 / #C0D0E0 | M66: 装饰性标题字；品牌图形 | N66: 0.9893 | O66: 0.276 | P66: 人工补录／坐标需复核 | Q66: 同 ID 表示跨图片重复文本，可共用译文。
A67: UI-0027 | B67: popup_quick__bg0.png | C67: No Data | D67: =IFERROR(VLOOKUP(A67,翻译清单!$A$6:$L$155,3,FALSE),"") -> 无数据 | E67: 1 | F67: 80 | G67: 96 | H67: 82 | I67: 14 | J67: 11 | K67: 多色标题、浅灰副标题 | L67: #D0E0F0 / #A0B0C0 / #B0C0D0 / #C0D0E0 | M67: 装饰性标题字；品牌图形 | N67: 0.9893 | O67: 1 | P67: 已人工校正 | Q67: 同 ID 表示跨图片重复文本，可共用译文。
A68: UI-0063 | B68: popup_system__bg0.png | C68: メッセージ速度 | D68: =IFERROR(VLOOKUP(A68,翻译清单!$A$6:$L$155,3,FALSE),"") -> 文本速度 | E68: 1 | F68: 38 | G68: 38 | H68: 138 | I68: 24 | J68: 20 | K68: 近黑色 | L68: #D0D0E0 / #000000 / #606070 / #909090 | M68: 明朝体／衬线体 | N68: 0.9993 | O68: 1 | P68: 已人工校正
A69: UI-0064 | B69: popup_system__bg0.png | C69: オートプレイ速度 | D69: =IFERROR(VLOOKUP(A69,翻译清单!$A$6:$L$155,3,FALSE),"") -> 自动播放速度 | E69: 1 | F69: 39 | G69: 78 | H69: 154 | I69: 23 | J69: 19 | K69: 近黑色 | L69: #D0D0E0 / #000000 / #404050 / #A0A0B0 | M69: 明朝体／衬线体 | N69: 0.9997 | O69: 1 | P69: 已人工校正
A70: UI-0065 | B70: popup_system__bg0.png | C70: ウィンドウ不透明度 | D70: =IFERROR(VLOOKUP(A70,翻译清单!$A$6:$L$155,3,FALSE),"") -> 窗口不透明度 | E70: 1 | F70: 38 | G70: 119 | H70: 155 | I70: 22 | J70: 18 | K70: 近黑色 | L70: #D0D0E0 / #000000 / #A0A0B0 / #303030 | M70: 明朝体／衬线体 | N70: 0.9991 | O70: 0.889 | P70: 已人工校正
A71: UI-0066 | B71: popup_system__bg0.png | C71: 未読スキップ | D71: =IFERROR(VLOOKUP(A71,翻译清单!$A$6:$L$155,3,FALSE),"") -> 跳过未读文本 | E71: 1 | F71: 37 | G71: 159 | H71: 119 | I71: 23 | J71: 19 | K71: 近黑色 | L71: #D0D0E0 / #000000 / #404050 / #606070 | M71: 明朝体／衬线体 | N71: 0.9987 | O71: 1 | P71: 已人工校正
A72: UI-0067 | B72: popup_system__pack.png | C72: 既読のみ | D72: =IFERROR(VLOOKUP(A72,翻译清单!$A$6:$L$155,3,FALSE),"") -> 仅已读 | E72: 5 | F72: 25 | G72: 0 | H72: 85 | I72: 24 | J72: 20 | K72: 黑字／蓝字 | L72: #000000 | M72: 粗黑体；普通与高亮状态 | N72: 0.9997 | O72: 1 | P72: 已人工校正
A73: UI-0068 | B73: popup_system__pack.png | C73: 全文 | D73: =IFERROR(VLOOKUP(A73,翻译清单!$A$6:$L$155,3,FALSE),"") -> 全部文本 | E73: 2 | F73: 21 | G73: 60 | H73: 49 | I73: 30 | J73: 25 | K73: 黑字／蓝字 | L73: #000000 / #5070B0 / #4080D0 / #305080 | M73: 粗黑体；普通与高亮状态 | N73: 0.9995 | O73: 1 | P73: 已人工校正
A74: UI-0069 | B74: popup_volume__bg0.png | C74: マスター | D74: =IFERROR(VLOOKUP(A74,翻译清单!$A$6:$L$155,3,FALSE),"") -> 主音量 | E74: 1 | F74: 37 | G74: 39 | H74: 79 | I74: 23 | J74: 19 | K74: 近黑色 | L74: #D0D0E0 / #000000 / #A0A0B0 / #C0D0E0 | M74: 明朝体／衬线体 | N74: 0.9997 | O74: 1 | P74: 已人工校正
A75: UI-0070 | B75: popup_volume__bg0.png | C75: BGM | D75: =IFERROR(VLOOKUP(A75,翻译清单!$A$6:$L$155,3,FALSE),"") -> BGM | E75: 1 | F75: 36 | G75: 80 | H75: 49 | I75: 19 | J75: 16 | K75: 近黑色 | L75: #D0D0E0 / #000000 / #A0A0B0 / #C0D0E0 | M75: 明朝体／衬线体 | N75: 0.9999 | O75: 1 | P75: 已人工校正
A76: UI-0071 | B76: popup_volume__bg0.png | C76: VOICE | D76: =IFERROR(VLOOKUP(A76,翻译清单!$A$6:$L$155,3,FALSE),"") -> 语音 | E76: 1 | F76: 37 | G76: 120 | H76: 68 | I76: 21 | J76: 17 | K76: 近黑色 | L76: #D0D0E0 / #000000 / #404050 / #808090 | M76: 明朝体／衬线体 | N76: 0.9998 | O76: 1 | P76: 已人工校正
A77: UI-0072 | B77: popup_volume__bg0.png | C77: SE（ゲーム効果音） | D77: =IFERROR(VLOOKUP(A77,翻译清单!$A$6:$L$155,3,FALSE),"") -> SE（游戏音效） | E77: 1 | F77: 36 | G77: 160 | H77: 122 | I77: 22 | J77: 18 | K77: 近黑色 | L77: #D0D0E0 / #000000 / #B0B0C0 / #505060 | M77: 明朝体／衬线体 | N77: 0.9902 | O77: 1 | P77: 已人工校正
A78: UI-0073 | B78: system1__pack.png | C78: 画面サイズ | D78: =IFERROR(VLOOKUP(A78,翻译清单!$A$6:$L$155,3,FALSE),"") -> 画面尺寸 | E78: 1 | F78: 447 | G78: 501 | H78: 171 | I78: 35 | J78: 29 | K78: 黑字／蓝字／白字 | L78: #F0F0F0 / #000000 | M78: 粗黑体；普通、悬停、启用、禁用状态 | N78: 0.999 | O78: 1 | P78: 已人工校正
A79: UI-0074 | B79: system1__pack.png | C79: 画面解像度 | D79: =IFERROR(VLOOKUP(A79,翻译清单!$A$6:$L$155,3,FALSE),"") -> 画面分辨率 | E79: 1 | F79: 288 | G79: 419 | H79: 328 | I79: 34 | J79: 28 | K79: 黑字／蓝字／白字 | L79: #F0F0F0 / #4080D0 / #000000 / #E0E0E0 | M79: 粗黑体；普通、悬停、启用、禁用状态 | N79: 0.9997 | O79: 0.825 | P79: 已人工校正
... A82: UI-0077 | B82: system1__pack.png | C82: システムメニューポップアップ | D82: =IFERROR(VLOOKUP(A82,翻译清单!$A$6:$L$155,3,FALSE),"") -> 系统菜单弹出 | E82: 1 | F82: 5 | G82: 2 | H82: 480 | I82: 29 | J82: 24 | K82: 黑字／蓝字／白字 | L82: #F0F0F0 | M82: 粗黑体；普通、悬停、启用、禁用状态 | N82: 0.9826 | O82: 0.977 | P82: 已人工校正
A83: UI-0017 | B83: system1__pack.png | C83: サスペンド機能 | D83: =IFERROR(VLOOKUP(A83,翻译清单!$A$6:$L$155,3,FALSE),"") -> 暂停功能 | E83: 1 | F83: 25 | G83: 371 | H83: 31 | I83: 34 | J83: 28 | K83: 黑字／蓝字／白字 | L83: #F0F0F0 / #000000 | M83: 粗黑体；普通、悬停、启用、禁用状态 | N83: 0.9994 | O83: 0.7 | P83: 已人工校正／坐标需复核 | Q83: 同 ID 表示跨图片重复文本，可共用译文。
A84: UI-0079 | B84: system1__pack.png | C84: マウスの設定 | D84: =IFERROR(VLOOKUP(A84,翻译清单!$A$6:$L$155,3,FALSE),"") -> 鼠标设置 | E84: 1 | F84: 1 | G84: 369 | H84: 25 | I84: 31 | J84: 25 | K84: 黑字／蓝字／白字 | L84: #000000 / #F0F0F0 / #E0E0E0 / #D0D0D0 | M84: 粗黑体；普通、悬停、启用、禁用状态 | N84: 0.9964 | O84: 0.708 | P84: 已人工校正／坐标需复核
A85: UI-0080 | B85: system1__pack.png | C85: スナップショットの保存設定 | D85: =IFERROR(VLOOKUP(A85,翻译清单!$A$6:$L$155,3,FALSE),"") -> 截图保存设置 | E85: 1 | F85: 1 | G85: 369 | H85: 25 | I85: 31 | J85: 25 | K85: 黑字／蓝字／白字 | L85: #000000 / #F0F0F0 / #E0E0E0 / #D0D0D0 | M85: 粗黑体；普通、悬停、启用、禁用状态 | N85: 0.9964 | O85: 0.677 | P85: 已人工校正／坐标需复核
A86: UI-0081 | B86: system1__pack.png | C86: 日時ファイル名で保存 | D86: =IFERROR(VLOOKUP(A86,翻译清单!$A$6:$L$155,3,FALSE),"") -> 以日期时间文件名保存 | E86: 2 | F86: 53 | G86: 97 | H86: 291 | I86: 30 | J86: 25 | K86: 黑字／蓝字／白字 | L86: #000000 / #F0F0F0 | M86: 粗黑体；普通、悬停、启用、禁用状态 | N86: 0.9944 | O86: 1 | P86: 已人工校正
A87: UI-0082 | B87: system1__pack.png | C87: ファイル名を指定 | D87: =IFERROR(VLOOKUP(A87,翻译清单!$A$6:$L$155,3,FALSE),"") -> 指定文件名 | E87: 3 | F87: 327 | G87: 159 | H87: 247 | I87: 31 | J87: 25 | K87: 黑字／蓝字／白字 | L87: #4080D0 / #F0F0F0 / #000000 | M87: 粗黑体；普通、悬停、启用、禁用状态 | N87: 0.9968 | O87: 1 | P87: 已人工校正
A88: UI-0083 | B88: system1__pack.png | C88: フルスクリーン | D88: =IFERROR(VLOOKUP(A88,翻译清单!$A$6:$L$155,3,FALSE),"") -> 全屏 | E88: 4 | F88: 53 | G88: 279 | H88: 236 | I88: 32 | J88: 26 | K88: 黑字／蓝字／白字 | L88: #4080D0 / #F0F0F0 / #000000 / #E0E0E0 | M88: 粗黑体；普通、悬停、启用、禁用状态 | N88: 0.9997 | O88: 1 | P88: 已人工校正
A89: UI-0084 | B89: system1__pack.png | C89: ウィンドウ | D89: =IFERROR(VLOOKUP(A89,翻译清单!$A$6:$L$155,3,FALSE),"") -> 窗口 | E89: 1 | F89: 493 | G89: 477 | H89: 145 | I89: 28 | J89: 23 | K89: 黑字／蓝字／白字 | L89: #000000 | M89: 粗黑体；普通、悬停、启用、禁用状态 | N89: 0.9037 | O89: 0.8 | P89: 已人工校正／坐标需复核
A90: UI-0085 | B90: system1__pack.png | C90: 1024×576 | D90: =IFERROR(VLOOKUP(A90,翻译清单!$A$6:$L$155,3,FALSE),"") -> 1024×576 | E90: 3 | F90: 303 | G90: 282 | H90: 170 | I90: 27 | J90: 22 | K90: 黑字／蓝字／白字 | L90: #4080D0 / #F0F0F0 | M90: 粗黑体；普通、悬停、启用、禁用状态 | N90: 0.9996 | O90: 1 | P90: 已人工校正
...

Sheet OCR原始明细
A1: OCR 原始明细（查漏用）
A2: 机器识别未经人工逐条纠错；相邻图块可能被拼接，不要直接把本页当作翻译原文。
A5: OCR ID | B5: 文件名 | C5: 机器识别文本 | D5: 置信度 | E5: X | F5: Y | G5: 宽 | H5: 高 | I5: 方向 | J5: 估计字号(px) | K5: 候选色值 | L5: 识别底色 | M5: 状态
A6: OCR-0001 | B6: dialog__pack.png | C6: V | D6: 0.472 | E6: 559 | F6: 38 | G6: 25 | H6: 31 | I6: 横排 | J6: 25 | K6: #C0C0E0 / #7080B0 / #7080C0 / #8090C0 | L6: 亮底 | M6: 需复核
A7: OCR-0002 | B7: dialog__pack.png | C7: K | D7: 0.5588 | E7: 33 | F7: 43 | G7: 21 | H7: 24 | I7: 横排 | J7: 20 | K7: #C0C0E0 / #6080B0 / #7090C0 / #7080C0 | L7: 暗底 | M7: 需复核
A8: OCR-0003 | B8: dialog__pack.png | C8: この機能が不要な場合は「OFF」を選択してください。 | D8: 0.9969 | E8: 0 | F8: 297 | G8: 541 | H8: 23 | I8: 横排 | J8: 19 | K8: #304070 / #F0F0F0 | L8: 亮底 | M8: 原始识别
A9: OCR-0004 | B9: dialog__pack.png | C9: システム設定画面でいつでも再設定が可能です。YESYESNO | D9: 0.9925 | E9: 24 | F9: 316 | G9: 690 | H9: 41 | I9: 横排 | J9: 34 | K9: #304070 / #4080D0 / #F0F0F0 / #000000 | L9: 暗底 | M9: 原始识别
A10: OCR-0005 | B10: dialog__pack.png | C10: データを入れ替えをしますか?0次回から表示しない0F日 | D10: 0.9282 | E10: 0 | F10: 343 | G10: 803 | H10: 43 | I10: 横排 | J10: 35 | K10: #F0F0F0 / #4080D0 / #304070 / #5070B0 | L10: 亮底 | M10: 原始识别
A11: OCR-0006 | B11: dialog__pack.png | C11: OFFON | D11: 0.9995 | E11: 708 | F11: 380 | G11: 101 | H11: 25 | I11: 横排 | J11: 20 | K11: #4080D0 / #F0F0F0 / #000000 | L11: 暗底 | M11: 原始识别
A12: OCR-0007 | B12: dialog__pack.png | C12: 前回の続きから始めますか? | D12: 0.9628 | E12: 1 | F12: 382 | G12: 515 | H12: 36 | I12: 横排 | J12: 30 | K12: #F0F0F0 / #5070B0 / #5060A0 / #E0E0E0 | L12: 亮底 | M12: 原始识别
A13: OCR-0008 | B13: dialog__pack.png | C13: 次回から表示しない | D13: 1 | E13: 525 | F13: 390 | G13: 188 | H13: 23 | I13: 横排 | J13: 19 | K13: #000000 | L13: 暗底 | M13: 原始识别
A14: OCR-0009 | B14: dialog__pack.png | C14: タイトル画面に戻りますか？ | D14: 0.9744 | E14: 1 | F14: 415 | G14: 507 | H14: 36 | I14: 横排 | J14: 30 | K14: #F0F0F0 / #4080D0 / #E0E0E0 / #D0D0D0 | L14: 亮底 | M14: 原始识别
A15: OCR-0010 | B15: dialog__pack.png | C15: 次回から表示しない | D15: 1 | E15: 523 | F15: 425 | G15: 188 | H15: 23 | I15: 横排 | J15: 19 | K15: #4080D0 | L15: 暗底 | M15: 原始识别
A16: OCR-0011 | B16: dialog__pack.png | C16: データをコピーしますか？ | D16: 0.9631 | E16: 0 | F16: 445 | G16: 444 | H16: 41 | I16: 横排 | J16: 34 | K16: #F0F0F0 / #4080D0 / #000000 / #4070C0 | L16: 亮底 | M16: 原始识别
A17: OCR-0012 | B17: dialog__pack.png | C17: クイックセーブしますか？ | D17: 0.9893 | E17: 0 | F17: 479 | G17: 441 | H17: 45 | I17: 横排 | J17: 37 | K17: #F0F0F0 / #000000 | L17: 亮底 | M17: 原始识别
... A448: OCR-0443 | B448: title_bg_6.png | C448: 体験版 | D448: 0.9544 | E448: 105 | F448: 83 | G448: 285 | H448: 127 | I448: 横排 | J448: 104 | K448: #203060 / #F0F0F0 / #607090 / #90A0B0 | L448: 亮底 | M448: 原始识别

Sheet 图片清单
A1: uipsd PNG 图片清单
A2: 52 张图片的尺寸、扫描状态、文本条目数和来源路径。
A5: 文件名 | B5: 类别 | C5: 尺寸 | D5: 透明通道 | E5: 扫描状态 | F5: 整理条目数 | G5: OCR框数 | H5: 备注 | I5: 相对路径 | J5: SHA-256
A6: backlog__bg0.png | B6: 背景 | C6: 1920 × 1080 | D6: 有 | E6: 未见需翻译文字 | F6: 0 | G6: 0 | I6: extracted/_tlg_png/uipsd/backlog__bg0.png | J6: 9dc388d13c7f50c7dd9a015d9df70ff7515388eeff2d2a45b1a8592b0dd13e4b
A7: backlog__pack.png | B7: 图集 | C7: 1380 × 104 | D7: 有 | E7: 已有中文 | F7: 0 | G7: 0 | H7: 检测为已修改中文图集；本轮不重复翻译。 | I7: extracted/_tlg_png/uipsd/backlog__pack.png | J7: 31861f8e86e16b66a17ac328571f3593c478863c93aade787299f1c4884df183
A8: dialog__bg0.png | B8: 背景 | C8: 1920 × 1080 | D8: 有 | E8: 未见需翻译文字 | F8: 0 | G8: 0 | I8: extracted/_tlg_png/uipsd/dialog__bg0.png | J8: dca62b75765310366670b331aa45072f98548e69d6b5c01454a21eb8fc3a71b6
A9: dialog__pack.png | B9: 图集 | C9: 813 × 831 | D9: 有 | E9: 含文字／已整理 | F9: 21 | G9: 23 | I9: extracted/_tlg_png/uipsd/dialog__pack.png | J9: c14d629aa0fe235c0bab4676fc9fbfb4190c539ec33f934fae565b8e64e8f790
A10: file__pack.png | B10: 图集 | C10: 1099 × 1089 | D10: 有 | E10: 含文字／已整理 | F10: 19 | G10: 56 | I10: extracted/_tlg_png/uipsd/file__pack.png | J10: c6ad9c07d11ef91c46b06ce1182d48adc08306a6becc8dc0af31bd03fd8f6143
A11: file_load__bg0.png | B11: 背景 | C11: 1920 × 1080 | D11: 无 | E11: 未见需翻译文字 | F11: 0 | G11: 0 | I11: extracted/_tlg_png/uipsd/file_load__bg0.png | J11: 5b1ae7eaa619118f5c1b502c67f714c477da3d8abbf4b66b06c46252530082dd
A12: file_quick__bg0.png | B12: 背景 | C12: 1920 × 1080 | D12: 无 | E12: 未见需翻译文字 | F12: 0 | G12: 0 | I12: extracted/_tlg_png/uipsd/file_quick__bg0.png | J12: 370a27feb0b8064ae8a004d1af6c5fa090145caef595dec30c518c430e967411
A13: file_save__bg0.png | B13: 背景 | C13: 1920 × 1080 | D13: 无 | E13: 未见需翻译文字 | F13: 0 | G13: 0 | I13: extracted/_tlg_png/uipsd/file_save__bg0.png | J13: ec936fd49121f4c9004d0e6ba95d4485884f5554e5f3b8cc93e730b33ca9f58c
A14: file_voice__bg0.png | B14: 背景 | C14: 1920 × 1080 | D14: 无 | E14: 未见需翻译文字 | F14: 0 | G14: 0 | I14: extracted/_tlg_png/uipsd/file_voice__bg0.png | J14: 0b693e27b385d138e7ada05f3300ff68625f08e674fcec4b3d11643a1e63f7b4
A15: file_voice__pack.png | B15: 图集 | C15: 780 × 821 | D15: 有 | E15: 含文字／已整理 | F15: 7 | G15: 31 | I15: extracted/_tlg_png/uipsd/file_voice__pack.png | J15: 45d231fa9701881d6da21bf70b0eb43214279ac5712e7213bca1179baa1730e3
A16: gesture_tips__bg0.png | B16: 背景 | C16: 56 × 80 | D16: 有 | E16: 未见需翻译文字 | F16: 0 | G16: 0 | I16: extracted/_tlg_png/uipsd/gesture_tips__bg0.png | J16: 7b9d27c9510c26820432d4faf1590b4a719eb522128bb3bb616e4a3ebd906d06
A17: gesture_tips__pack.png | B17: 图集 | C17: 312 × 241 | D17: 有 | E17: 含文字／已整理 | F17: 12 | G17: 16 | I17: extracted/_tlg_png/uipsd/gesture_tips__pack.png | J17: d926dd6302abf6ae57b5aa255e42c2516f480adfb7f758f3ed863fb7597201c2
A18: gview__pack.png | B18: 图集 | C18: 168 × 660 | D18: 有 | E18: 未见需翻译文字 | F18: 0 | G18: 0 | I18: extracted/_tlg_png/uipsd/gview__pack.png | J18: c2eb198f908de709129b96524329bbec71090507b722504413097b2212b99ac4
A19: message__bg0.png | B19: 背景 | C19: 1920 × 334 | D19: 有 | E19: 未见需翻译文字 | F19: 0 | G19: 0 | I19: extracted/_tlg_png/uipsd/message__bg0.png | J19: 722bef430c2950146b0e27edbc5558bbe605c6a187ebfa0c9777f30e27ab8507
... A33: popup_volume__pack.png | B33: 图集 | C33: 82 × 78 | D33: 有 | E33: 未见需翻译文字 | F33: 0 | G33: 0 | I33: extracted/_tlg_png/uipsd/popup_volume__pack.png | J33: 57c4dad10c8f01c8e3a3969160d03dc10708c10b241f92e60210daf6f6f10252
A34: select__bg0.png | B34: 背景 | C34: 1920 × 1080 | D34: 有 | E34: 未见需翻译文字 | F34: 0 | G34: 0 | H34: 纯背景／透明层，无固定文字。 | I34: extracted/_tlg_png/uipsd/select__bg0.png | J34: 0025d0eb3675aac8203cc7436f1284363ddbde2b223b7e26e6692eeb348775f9
A35: select__pack.png | B35: 图集 | C35: 1434 × 430 | D35: 有 | E35: 未见需翻译文字 | F35: 0 | G35: 0 | I35: extracted/_tlg_png/uipsd/select__pack.png | J35: 1e049fb2476eb08dd3cfa7cb6e849c1c1117cf72e0bf691e03364e25ca6e711d
A36: system0__pack.png | B36: 图集 | C36: 427 × 462 | D36: 有 | E36: 已有中文 | F36: 0 | G36: 0 | H36: 检测为已修改中文系统导航图集；本轮不重复翻译。 | I36: extracted/_tlg_png/uipsd/system0__pack.png | J36: 5a08e5d03e467bcf58cf260709eac1e45ca7a07e3f06ceef37dfeeed2eab6c22
A37: system1__bg0.png | B37: 背景 | C37: 1920 × 1080 | D37: 无 | E37: 未见需翻译文字 | F37: 0 | G37: 0 | I37: extracted/_tlg_png/uipsd/system1__bg0.png | J37: c82cfd9c7eb0e520148112870267995a378650265c481169e049be795240bf3f
A38: system1__pack.png | B38: 图集 | C38: 659 × 651 | D38: 有 | E38: 含文字／已整理 | F38: 27 | G38: 63 | I38: extracted/_tlg_png/uipsd/system1__pack.png | J38: 88c8bec720aae0518115f99ad59b97a3475064f175a5a52236f9d11157ede73b
A39: system2__bg0.png | B39: 背景 | C39: 1920 × 1080 | D39: 无 | E39: 未见需翻译文字 | F39: 0 | G39: 0 | I39: extracted/_tlg_png/uipsd/system2__bg0.png | J39: 192d9307a8f39ccaaaff94fdf31193af3f5595fe38ea7e5e21e3070418101a8d
A40: system2__pack.png | B40: 图集 | C40: 543 × 559 | D40: 有 | E40: 含文字／已整理 | F40: 18 | G40: 30 | I40: extracted/_tlg_png/uipsd/system2__pack.png | J40: 4a240bbd41a7d4dcb427f06964767d9355269b44e44ad0b348d352e0742471ab
A41: system3__bg0.png | B41: 背景 | C41: 1920 × 1080 | D41: 无 | E41: 未见需翻译文字 | F41: 0 | G41: 0 | I41: extracted/_tlg_png/uipsd/system3__bg0.png | J41: d2e300f5361303b4467105f5ff9a90cd7fa9091a0e70618f10f1e0e31c7a448b
A42: system3__pack.png | B42: 图集 | C42: 1260 × 1296 | D42: 有 | E42: 含文字／已整理 | F42: 20 | G42: 30 | I42: extracted/_tlg_png/uipsd/system3__pack.png | J42: 30c55beceb78102d5fe67a71a5cd1fc8b200f24d7a03c161c9e18a5b533586ba
A43: system4__bg0.png | B43: 背景 | C43: 1920 × 1080 | D43: 无 | E43: 未见需翻译文字 | F43: 0 | G43: 0 | I43: extracted/_tlg_png/uipsd/system4__bg0.png | J43: b7b1d6a01eb2d2e621031628b246b634d9d7f95a97a99dd27e717ca2bb2ba841
A44: system4__pack.png | B44: 图集 | C44: 419 × 255 | D44: 有 | E44: 含文字／已整理 | F44: 10 | G44: 27 | I44: extracted/_tlg_png/uipsd/system4__pack.png | J44: c6fa04bdcb47ea544f2b14ab192aa13eafd75038640f7563ca24438afb0ef150
A45: system5__bg0.png | B45: 背景 | C45: 1920 × 1080 | D45: 无 | E45: 未见需翻译文字 | F45: 0 | G45: 0 | I45: extracted/_tlg_png/uipsd/system5__bg0.png | J45: 893e8956d2d45b3b2f578bee778be791d276da4ddf7d7f6eb443467e75bd4a05
A46: system5__pack.png | B46: 图集 | C46: 1068 × 598 | D46: 有 | E46: 含文字／已整理 | F46: 15 | G46: 24 | I46: extracted/_tlg_png/uipsd/system5__pack.png | J46: cdcf937cbe784f53b84438f6bdd2cc523aa492c7834545824aced3029ffcb10e
A47: system5_pulldown__bg0.png | B47: 背景 | C47: 564 × 288 | D47: 有 | E47: 未见需翻译文字 | F47: 0 | G47: 0 | I47: extracted/_tlg_png/uipsd/system5_pulldown__bg0.png | J47: bd2b8b94de780985ad41569a425f0747c5a469bdbfbe55331217ea542b65059f
A48: system5_pulldown__pack.png | B48: 图集 | C48: 592 × 752 | D48: 有 | E48: 含文字／已整理 | F48: 16 | G48: 53 | I48: extracted/_tlg_png/uipsd/system5_pulldown__pack.png | J48: 75f5a05f021bc881c080b5edd456f19a370a113d0f9ff4a5dc96be39f5379b9b
... A51: system6_pulldown__pack.png | B51: 图集 | C51: 336 × 288 | D51: 有 | E51: 含文字／已整理 | F51: 4 | G51: 14 | I51: extracted/_tlg_png/uipsd/system6_pulldown__pack.png | J51: b1f32546a1c37302b4609a2500e2f6b34eaf116bb2c5f2dfcd2e58eb75c9f384
A52: title__pack.png | B52: 图集 | C52: 419 × 406 | D52: 有 | E52: 已有中文 | F52: 0 | G52: 0 | H52: 检测为已修改中文标题菜单图集；本轮不重复翻译。 | I52: extracted/_tlg_png/uipsd/title__pack.png | J52: b66508d892f0ca6ec67c740c8c10603e1baae507182acdd160caef414e95c8ae
A53: title_bg_2.png | B53: 背景 | C53: 1928 × 1088 | D53: 有 | E53: 含文字／已整理 | F53: 1 | G53: 4 | H53: 仅版权信息，建议保留原文。 | I53: extracted/_tlg_png/uipsd/title_bg_2.png | J53: 69b91f8498f1e2d43ed0e1e4ec7b2e503f4fae4dcfffafd17e5ea05fd2c33341
A54: title_bg_3.png | B54: 背景 | C54: 635 × 580 | D54: 有 | E54: 未见需翻译文字 | F54: 0 | G54: 0 | I54: extracted/_tlg_png/uipsd/title_bg_3.png | J54: f99d503917799783704229b38ebd283b9c9521a7a493b4feb17df91646541e64
A55: title_bg_4.png | B55: 背景 | C55: 843 × 523 | D55: 有 | E55: 未见需翻译文字 | F55: 0 | G55: 0 | I55: extracted/_tlg_png/uipsd/title_bg_4.png | J55: 233cf283df3435a1d026c5f6b80d7a31b3bf18d411d30d82ddc664f3180a9d17
A56: title_bg_5.png | B56: 背景 | C56: 1578 × 508 | D56: 有 | E56: 含文字／已整理 | F56: 2 | G56: 4 | I56: extracted/_tlg_png/uipsd/title_bg_5.png | J56: bbb4846e3fcd7c301118662df6ca766a81353fe3e204d8413f2063587a89f2af
A57: title_bg_6.png | B57: 背景 | C57: 474 × 257 | D57: 有 | E57: 含文字／已整理 | F57: 1 | G57: 2 | I57: extracted/_tlg_png/uipsd/title_bg_6.png | J57: 4ca43f4d5ac4d8705b9fad2b43396bc7fd888e526024eeb798fb5a2e2db7f523
